Workbook
Name Slicer_Genre: #N/A
Name Slicer_Genre1: #N/A
Name Slicer_Publication_Year: #N/A
Name Slicer_Publication_Year1: #N/A
Name Slicer_Shelf_Code: #N/A

Sheet DATA_SET
A1: BOOK DATSETS
A2: Book ID | B2: Title | C2: Author | D2: Genre | E2: ISBN | F2: Publisher | G2: Publication Year | H2: Edition | I2: Pages | J2: Shelf Code | K2: Availability Status | L2: Issue Date | M2: Return Date | N2: Cost | O2: Category | P2: Book Condition | Q2: No. Of Rewiew | R2: Barcode
A3: BK1 | B3: NCERT Social Science | C3: Jerry Andrews | D3: Social Science | E3: 978-1-4284-2336-7 | F3: NCERT | G3: 2010 | H3: 3rd | I3: 464 | J3: D3 | K3: Available | N3: 1310 | O3: Education | P3: NEW | Q3: 137 | R3: ="*"&Q3&"*" -> *137*
A4: BK2 | B4: RS Aggarwal Mathematics | C4: Christine Reed | D4: Maths | E4: 978-0-7116-2302-6 | F4: Macmillan | G4: 2011 | H4: 2nd | I4: 417 | J4: C3 | K4: Issued | L4: 45036 | M4: 45427 | N4: 1680 | O4: Education | P4: WORN | Q4: 432 | R4: ="*"&Q4&"*" -> *432*
A5: BK3 | B5: English Grammar & Composition | C5: Mary Rodriguez | D5: English | E5: 978-0-87574-204-5 | F5: Macmillan | G5: 2022 | H5: 2nd | I5: 257 | J5: A3 | K5: Issued | L5: 45116 | M5: 45400 | N5: 535 | O5: Language | P5: NEW | Q5: 323 | R5: ="*"&Q5&"*" -> *323*
A6: BK4 | B6: Together with EVS | C6: Curtis Coleman | D6: EVS | E6: 978-1-09-663728-8 | F6: Pearson | G6: 2017 | H6: 2nd | I6: 98 | J6: B2 | K6: Available | N6: 280 | O6: Science | P6: AVG | Q6: 300 | R6: ="*"&Q6&"*" -> *300*
A7: BK5 | B7: NCERT Maths | C7: Eric Foster | D7: Maths | E7: 978-0-359-45210-1 | F7: Cambridge | G7: 2008 | H7: 1st | I7: 141 | J7: C4 | K7: Issued | L7: 45461 | M7: 45506 | N7: 2335 | O7: Education | P7: NEW | Q7: 356 | R7: ="*"&Q7&"*" -> *356*
A8: BK6 | B8: Truemanâ€™s Biology | C8: Andrew Williams | D8: Biology | E8: 978-0-604-72900-2 | F8: Scholastic | G8: 2023 | H8: 1st | I8: 297 | J8: B4 | K8: Available | N8: 1690 | O8: General | P8: AVG | Q8: 166 | R8: ="*"&Q8&"*" -> *166*
A9: BK7 | B9: NCERT Economics | C9: Charlotte Payne | D9: Economics | E9: 978-0-09-441985-8 | F9: Cambridge | G9: 2015 | H9: 1st | I9: 154 | J9: D3 | K9: Available | N9: 1400 | O9: General | P9: AVG | Q9: 317 | R9: ="*"&Q9&"*" -> *317*
A10: BK8 | B10: Modern ABC Chemistry | C10: Terri Escobar | D10: Chemistry | E10: 978-0-9881973-4-3 | F10: Oxford | G10: 2019 | H10: 1st | I10: 307 | J10: B2 | K10: Issued | L10: 45601 | M10: 45714 | N10: 765 | O10: General | P10: AVG | Q10: 235 | R10: ="*"&Q10&"*" -> *235*
A11: BK9 | B11: NCERT Economics | C11: Cheryl Hudson | D11: Economics | E11: 978-0-235-08798-4 | F11: Macmillan | G11: 2018 | H11: 2nd | I11: 245 | J11: D3 | K11: Issued | L11: 45377 | M11: 45593 | N11: 2440 | O11: General | P11: NEW | Q11: 183 | R11: ="*"&Q11&"*" -> *183*
A12: BK10 | B12: NCERT Economics | C12: Tammy Johnson | D12: Economics | E12: 978-1-00-305026-1 | F12: Oxford | G12: 2012 | H12: 2nd | I12: 86 | J12: C3 | K12: Issued | L12: 45370 | M12: 45384 | N12: 865 | O12: General | P12: WORN | Q12: 216 | R12: ="*"&Q12&"*" -> *216*
A13: BK11 | B13: TS Grewal Accountancy | C13: Sherry Guerrero | D13: Accountancy | E13: 978-0-250-34438-3 | F13: Scholastic | G13: 2005 | H13: 3rd | I13: 94 | J13: E1 | K13: Available | N13: 415 | O13: General | P13: AVG | Q13: 171 | R13: ="*"&Q13&"*" -> *171*
A14: BK12 | B14: Computer Science with Python | C14: Sonya Ewing | D14: Computer Science | E14: 978-0-09-204326-0 | F14: Macmillan | G14: 2015 | H14: 2nd | I14: 248 | J14: C2 | K14: Issued | L14: 45606 | M14: 45626 | N14: 1285 | O14: General | P14: AVG | Q14: 329 | R14: ="*"&Q14&"*" -> *329*
A15: BK13 | B15: Oxford English Reader | C15: Donald Wilson | D15: English | E15: 978-0-89919-815-6 | F15: Cambridge | G15: 2020 | H15: 1st | I15: 465 | J15: C1 | K15: Issued | L15: 45668 | M15: 45676 | N15: 1250 | O15: Language | P15: AVG | Q15: 152 | R15: ="*"&Q15&"*" -> *152*
A16: BK14 | B16: Python Programming - Balagurusamy | C16: Brandon Johnson | D16: Computer Science | E16: 978-0-86311-103-7 | F16: Oxford | G16: 2013 | H16: 3rd | I16: 355 | J16: A1 | K16: Issued | L16: 45506 | M16: 45581 | N16: 2085 | O16: General | P16: WORN | Q16: 443 | R16: ="*"&Q16&"*" -> *443*
A17: BK15 | B17: Fundamentals of Physics - Resnick Halliday | C17: Michael Dyer | D17: Physics | E17: 978-0-87127-487-8 | F17: Macmillan | G17: 2016 | H17: 3rd | I17: 385 | J17: B2 | K17: Available | N17: 155 | O17: General | P17: WORN | Q17: 214 | R17: ="*"&Q17&"*" -> *214*
A18: BK16 | B18: Together with EVS | C18: Kimberly Nunez | D18: EVS | E18: 978-0-482-35012-1 | F18: Macmillan | G18: 2021 | H18: 3rd | I18: 371 | J18: D3 | K18: Available | N18: 2440 | O18: Science | P18: WORN | Q18: 114 | R18: ="*"&Q18&"*" -> *114*
A19: BK17 | B19: NCERT Business Studies | C19: Edward West II | D19: Business Studies | E19: 978-0-365-52363-5 | F19: Pearson | G19: 2007 | H19: 2nd | I19: 216 | J19: A4 | K19: Issued | L19: 45343 | M19: 45503 | N19: 335 | O19: General | P19: NEW | Q19: 346 | R19: ="*"&Q19&"*" -> *346*
A20: BK18 | B20: NCERT Maths | C20: Joann Oneal | D20: Maths | E20: 978-0-618-65377-5 | F20: Pearson | G20: 2011 | H20: 3rd | I20: 396 | J20: D2 | K20: Issued | L20: 44986 | M20: 45461 | N20: 995 | O20: Education | P20: AVG | Q20: 121 | R20: ="*"&Q20&"*" -> *121*
A21: BK19 | B21: Pearson Science Explorer | C21: Julie Price | D21: Science | E21: 978-0-337-45112-6 | F21: Pearson | G21: 2024 | H21: 2nd | I21: 274 | J21: A1 | K21: Issued | L21: 45496 | M21: 45535 | N21: 1660 | O21: Science | P21: WORN | Q21: 443 | R21: ="*"&Q21&"*" -> *443*
A22: BK20 | B22: Together with EVS | C22: Brittany Cooper | D22: EVS | E22: 978-1-924728-06-5 | F22: NCERT | G22: 2008 | H22: 2nd | I22: 95 | J22: D2 | K22: Available | N22: 1245 | O22: Science | P22: WORN | Q22: 343 | R22: ="*"&Q22&"*" -> *343*
A23: BK21 | B23: RD Sharma Mathematics | C23: Brandi Johnson | D23: Maths | E23: 978-0-488-48835-4 | F23: Scholastic | G23: 2018 | H23: 2nd | I23: 126 | J23: B2 | K23: Issued | L23: 45473 | M23: 45679 | N23: 195 | O23: Education | P23: NEW | Q23: 285 | R23: ="*"&Q23&"*" -> *285*
A24: BK22 | B24: Play with Maths | C24: Carolyn English | D24: Maths | E24: 978-1-04-745260-1 | F24: Macmillan | G24: 2024 | H24: 1st | I24: 393 | J24: E4 | K24: Issued | L24: 45517 | M24: 45649 | N24: 1300 | O24: Education | P24: NEW | Q24: 227 | R24: ="*"&Q24&"*" -> *227*
A25: BK23 | B25: Oxford English Reader | C25: Keith Arnold | D25: English | E25: 978-0-602-29994-1 | F25: Scholastic | G25: 2010 | H25: 1st | I25: 293 | J25: C1 | K25: Available | N25: 1910 | O25: Language | P25: AVG | Q25: 381 | R25: ="*"&Q25&"*" -> *381*
A26: BK24 | B26: NCERT Chemistry | C26: Lauren Smith | D26: Chemistry | E26: 978-1-360-54483-0 | F26: Macmillan | G26: 2007 | H26: 1st | I26: 235 | J26: C3 | K26: Available | N26: 725 | O26: General | P26: NEW | Q26: 271 | R26: ="*"&Q26&"*" -> *271*
A27: BK25 | B27: SL Arora Physics | C27: Jason Weaver | D27: Physics | E27: 978-1-58693-970-0 | F27: Oxford | G27: 2009 | H27: 1st | I27: 431 | J27: B3 | K27: Available | N27: 830 | O27: General | P27: WORN | Q27: 314 | R27: ="*"&Q27&"*" -> *314*
A28: BK26 | B28: DK Goel Accountancy | C28: Amanda Mayer | D28: Accountancy | E28: 978-0-88668-201-9 | F28: Cambridge | G28: 2014 | H28: 2nd | I28: 489 | J28: B3 | K28: Issued | L28: 45559 | M28: 45637 | N28: 910 | O28: General | P28: NEW | Q28: 157 | R28: ="*"&Q28&"*" -> *157*
A29: BK27 | B29: SL Arora Physics | C29: Jeffery Smith | D29: Physics | E29: 978-0-383-62121-4 | F29: Oxford | G29: 2017 | H29: 2nd | I29: 237 | J29: D4 | K29: Available | N29: 2225 | O29: General | P29: AVG | Q29: 360 | R29: ="*"&Q29&"*" -> *360*
A30: BK28 | B30: Fundamentals of Physics - Resnick Halliday | C30: Wanda Patterson | D30: Physics | E30: 978-0-317-21155-9 | F30: Pearson | G30: 2014 | H30: 3rd | I30: 273 | J30: E2 | K30: Available | N30: 1815 | O30: General | P30: NEW | Q30: 178 | R30: ="*"&Q30&"*" -> *178*
A31: BK29 | B31: Let Us C - Yashwant Kanetkar | C31: Rebecca Wilson | D31: Computer Science | E31: 978-0-500-08719-0 | F31: Scholastic | G31: 2008 | H31: 2nd | I31: 217 | J31: D2 | K31: Issued | L31: 45207 | M31: 45492 | N31: 2485 | O31: General | P31: AVG | Q31: 153 | R31: ="*"&Q31&"*" -> *153*
A32: BK30 | B32: S. Chand Business Studies | C32: Beth Morse | D32: Business Studies | E32: 978-1-4742-8919-1 | F32: Oxford | G32: 2009 | H32: 2nd | I32: 491 | J32: D2 | K32: Available | N32: 395 | O32: General | P32: AVG | Q32: 387 | R32: ="*"&Q32&"*" -> *387*
A33: BK31 | B33: Lakhmir Singh Science | C33: Jason Reid | D33: Science | E33: 978-0-919199-09-5 | F33: Oxford | G33: 2008 | H33: 2nd | I33: 337 | J33: A2 | K33: Issued | L33: 45568 | M33: 45648 | N33: 1530 | O33: Science | P33: AVG | Q33: 399 | R33: ="*"&Q33&"*" -> *399*
A34: BK32 | B34: S. Chand Business Studies | C34: Joshua Boyer | D34: Business Studies | E34: 978-1-57877-816-4 | F34: Scholastic | G34: 2015 | H34: 1st | I34: 331 | J34: B2 | K34: Issued | L34: 45242 | M34: 45455 | N34: 365 | O34: General | P34: NEW | Q34: 406 | R34: ="*"&Q34&"*" -> *406*
A35: BK33 | B35: Concepts of Physics - HC Verma | C35: Mary Moore | D35: Physics | E35: 978-1-08-701715-0 | F35: Scholastic | G35: 2021 | H35: 1st | I35: 126 | J35: A2 | K35: Available | N35: 1870 | O35: General | P35: WORN | Q35: 310 | R35: ="*"&Q35&"*" -> *310*
A36: BK34 | B36: NCERT Maths | C36: Carl Lucas DDS | D36: Maths | E36: 978-1-69553-976-1 | F36: Pearson | G36: 2019 | H36: 1st | I36: 298 | J36: C4 | K36: Available | N36: 2500 | O36: Education | P36: AVG | Q36: 202 | R36: ="*"&Q36&"*" -> *202*
A37: BK35 | B37: S. Chand EVS | C37: Chelsea Nelson | D37: EVS | E37: 978-0-7186-5776-5 | F37: Cambridge | G37: 2015 | H37: 1st | I37: 370 | J37: A2 | K37: Issued | L37: 45287 | M37: 45712 | N37: 345 | O37: Science | P37: AVG | Q37: 138 | R37: ="*"&Q37&"*" -> *138*
A38: BK36 | B38: SL Arora Physics | C38: Pamela Leonard | D38: Physics | E38: 978-0-18-837216-8 | F38: Macmillan | G38: 2008 | H38: 2nd | I38: 110 | J38: A3 | K38: Available | N38: 2100 | O38: General | P38: AVG | Q38: 234 | R38: ="*"&Q38&"*" -> *234*
A39: BK37 | B39: RS Aggarwal Mathematics | C39: David Nelson | D39: Maths | E39: 978-0-7977-9781-9 | F39: Oxford | G39: 2012 | H39: 2nd | I39: 184 | J39: E3 | K39: Issued | L39: 45696 | M39: 45712 | N39: 2160 | O39: Education | P39: WORN | Q39: 119 | R39: ="*"&Q39&"*" -> *119*
A40: BK38 | B40: NCERT Hindi | C40: Mary Perez | D40: Hindi | E40: 978-0-537-85195-5 | F40: Macmillan | G40: 2020 | H40: 3rd | I40: 158 | J40: A3 | K40: Issued | L40: 45062 | M40: 45082 | N40: 2015 | O40: General | P40: WORN | Q40: 210 | R40: ="*"&Q40&"*" -> *210*
...

Sheet OBJ-1
D8: COUNT | CA8: =D9 -> 0 | CB8: =D15 -> 77 | CC8: =ROUNDUP(D9/D15*100,0) -> 0
C9: Computer Science | CA9: =D10 -> 80 | CB9: =D15 -> 77 | CC9: =ROUNDUP(D10/D15*100,0) -> 104
C10: Cambridge | D10: 80 | BU10: =D10 -> 80 | BV10: =D16 -> 533 | BX10: =ROUNDUP(BU10/BV10*100,1) -> 15.1 | CA10: =D11 -> 98 | CB10: =D15 -> 77 | CC10: =ROUNDUP(D11/D15*100,0) -> 128
C11: Macmillan | D11: 98 | BU11: =D11 -> 98 | BV11: =D16 -> 533 | BX11: =ROUNDUP(BU11/BV11*100,1) -> 18.4 | CA11: =D12 -> 102 | CB11: =D15 -> 77 | CC11: =ROUNDUP(D12/D15*100,0) -> 133
C12: NCERT | D12: 102 | BU12: =D12 -> 102 | BV12: =D16 -> 533 | BX12: =ROUNDUP(BU12/BV12*100,1) -> 19.2 | CA12: =D13 -> 96 | CB12: =D15 -> 77 | CC12: =ROUNDUP(D13/D15*100,0) -> 125 | CE12: Cambridge | CF12: =D10 -> 80 | CG12: =ROUNDUP(AVERAGE(CF12:CF17),0) -> 89
C13: Oxford | D13: 96 | BU13: =D13 -> 96 | BV13: =D16 -> 533 | BX13: =ROUNDUP(BU13/BV13*100,1) -> 18.1 | CA13: =D14 -> 80 | CB13: =D15 -> 77 | CC13: =ROUNDUP(D14/D15*100,0) -> 104 | CE13: Macmillan | CF13: =D11 -> 98 | CG13: =ROUNDUP(AVERAGE(CF12:CF17),0) -> 89
C14: Pearson | D14: 80 | BU14: =D14 -> 80 | BV14: =D16 -> 533 | BX14: =ROUNDUP(BU14/BV14*100,1) -> 15.1 | CE14: NCERT | CF14: =D12 -> 102 | CG14: =ROUNDUP(AVERAGE(CF12:CF17),0) -> 89
C15: Scholastic | D15: 77 | BU15: =D15 -> 77 | BV15: =D16 -> 533 | BX15: =ROUNDUP(BU15/BV15*100,1) -> 14.5 | CE15: Oxford | CF15: =D13 -> 96 | CG15: =ROUNDUP(AVERAGE(CF12:CF17),0) -> 89
C16: Grand Total | D16: 533 | CE16: Pearson | CF16: =D14 -> 80 | CG16: =ROUNDUP(AVERAGE(CF12:CF17),0) -> 89
CE17: Scholastic | CF17: =D15 -> 77 | CG17: =ROUNDUP(AVERAGE(CF12:CF17),0) -> 89

Sheet OBJ-2
BX4: =VLOOKUP(C6, DATA_SET!A2:Q7354, 2, FALSE) -> Together with EVS
BX5: =VLOOKUP(C6, DATA_SET!A2:Q7354, 4, FALSE) -> EVS
C6: BK895 | BX6: =VLOOKUP(C6, DATA_SET!A2:Q7354, 6, FALSE) -> Pearson
BX7: =VLOOKUP(C6, DATA_SET!A2:Q7354, 14, FALSE) -> 1845
BX8: =VLOOKUP(C6, DATA_SET!A2:Q7354, 11, FALSE) -> Issued
BX9: =VLOOKUP(C6, DATA_SET!A2:Q7354, 15, FALSE) -> Science
B10: EX-BK1 - BK7352 | BX10: =VLOOKUP(C6, DATA_SET!A2:Q7354,3, FALSE) -> Hannah Knapp
BX11: =VLOOKUP(C6, DATA_SET!A2:Q7354,10, FALSE) -> E3
BX12: =VLOOKUP(C6, DATA_SET!A2:Q7354,15, FALSE) -> Science
BX13: =VLOOKUP(C6, DATA_SET!A2:Q7354,16, FALSE) -> NEW
BX14: =VLOOKUP(C6, DATA_SET!A2:Q7354,8, FALSE) -> 2nd
BX15: =VLOOKUP(C6, DATA_SET!A2:Q7354,7, FALSE) -> 2017 | BY15: 2025 | CA15: =BY15-BX15 -> 8
BX19: =VLOOKUP(C6, DATA_SET!A2:R7354,18, FALSE) -> *126*
BP25: 34
B26: Scan A Barcode For More Details… | BP26: 56
BP27: 53 | BT27: =BP26 -> 56
BT28: =BP26 -> 56
BY31: 450 | BZ31: 450

Sheet OBJ-3
F4: SUM
E5: 2013
E6: Cambridge | F6: 13822 | CH6: PUBLISHER | CI6: REVIE | CJ6: TOTAL
E7: Macmillan | F7: 17728 | CH7: =E6 -> Cambridge | CI7: =F6 -> 13822 | CJ7: =F12 -> 109047
E8: NCERT | F8: 20076 | CH8: =E7 -> Macmillan | CI8: =F7 -> 17728 | CJ8: =F12 -> 109047
E9: Oxford | F9: 20737 | CH9: =E8 -> NCERT | CI9: =F8 -> 20076 | CJ9: =F12 -> 109047
E10: Pearson | F10: 16050 | CH10: =E9 -> Oxford | CI10: =F9 -> 20737 | CJ10: =F12 -> 109047
E11: Scholastic | F11: 20634 | CH11: =E10 -> Pearson | CI11: =F10 -> 16050 | CJ11: =F12 -> 109047
E12: Grand Total | F12: 109047 | AH12: 2014 | CH12: =E11 -> Scholastic | CI12: =F11 -> 20634 | CJ12: =F12 -> 109047
AH13: Cambridge
AH14: Macmillan
F15: {=INDEX($E$6:$E$11, MATCH(ROW()-14, _xlfn.RANK.EQ($F$6:$F$11, $F$6:$F$11, 0), 0))} -> Oxford | G15: 1 | AH15: NCERT | CH15: {=INDEX($E$6:$E$11, MATCH(ROW()-14, _xlfn.RANK.EQ($F$6:$F$11, $F$6:$F$11, 0), 0))} -> Oxford | CI15: 1 | CK15: {=TEXT(INDEX($F$6:$F$11, MATCH(ROW()-14, _xlfn.RANK.EQ($F$6:$F$11, $F$6:$F$11, 0), 0))/1000, "0.0") & "K"} -> 20.7K
F16: {=INDEX($E$6:$E$11, MATCH(ROW()-14, _xlfn.RANK.EQ($F$6:$F$11, $F$6:$F$11, 0), 0))} -> Scholastic | G16: 2 | AH16: Oxford | CH16: {=INDEX($E$6:$E$11, MATCH(ROW()-14, _xlfn.RANK.EQ($F$6:$F$11, $F$6:$F$11, 0), 0))} -> Scholastic | CI16: 2 | CK16: {=TEXT(INDEX($F$6:$F$11, MATCH(ROW()-14, _xlfn.RANK.EQ($F$6:$F$11, $F$6:$F$11, 0), 0))/1000, "0.0") & "K"} -> 20.6K
F17: {=INDEX($E$6:$E$11, MATCH(ROW()-14, _xlfn.RANK.EQ($F$6:$F$11, $F$6:$F$11, 0), 0))} -> NCERT | G17: 3 | AH17: Pearson | CH17: {=INDEX($E$6:$E$11, MATCH(ROW()-14, _xlfn.RANK.EQ($F$6:$F$11, $F$6:$F$11, 0), 0))} -> NCERT | CI17: 3 | CK17: {=TEXT(INDEX($F$6:$F$11, MATCH(ROW()-14, _xlfn.RANK.EQ($F$6:$F$11, $F$6:$F$11, 0), 0))/1000, "0.0") & "K"} -> 20.1K
F18: {=INDEX($E$6:$E$11, MATCH(ROW()-14, _xlfn.RANK.EQ($F$6:$F$11, $F$6:$F$11, 0), 0))} -> Macmillan | G18: 4 | AH18: Scholastic | CH18: {=INDEX($E$6:$E$11, MATCH(ROW()-14, _xlfn.RANK.EQ($F$6:$F$11, $F$6:$F$11, 0), 0))} -> Macmillan | CI18: 4 | CK18: {=TEXT(INDEX($F$6:$F$11, MATCH(ROW()-14, _xlfn.RANK.EQ($F$6:$F$11, $F$6:$F$11, 0), 0))/1000, "0.0") & "K"} -> 17.7K
F19: {=INDEX($E$6:$E$11, MATCH(ROW()-14, _xlfn.RANK.EQ($F$6:$F$11, $F$6:$F$11, 0), 0))} -> Pearson | G19: 5 | AH19: Grand Total | CH19: {=INDEX($E$6:$E$11, MATCH(ROW()-14, _xlfn.RANK.EQ($F$6:$F$11, $F$6:$F$11, 0), 0))} -> Pearson | CI19: 5 | CK19: {=TEXT(INDEX($F$6:$F$11, MATCH(ROW()-14, _xlfn.RANK.EQ($F$6:$F$11, $F$6:$F$11, 0), 0))/1000, "0.0") & "K"} -> 16.1K
F20: {=INDEX($E$6:$E$11, MATCH(ROW()-14, _xlfn.RANK.EQ($F$6:$F$11, $F$6:$F$11, 0), 0))} -> Cambridge | G20: 6 | CH20: {=INDEX($E$6:$E$11, MATCH(ROW()-14, _xlfn.RANK.EQ($F$6:$F$11, $F$6:$F$11, 0), 0))} -> Cambridge | CI20: 6 | CK20: {=TEXT(INDEX($F$6:$F$11, MATCH(ROW()-14, _xlfn.RANK.EQ($F$6:$F$11, $F$6:$F$11, 0), 0))/1000, "0.0") & "K"} -> 13.8K

Sheet OBJ-4
I4: COUNT
H5: C1
H6: Available | I6: 196 | AG6: =I6 -> 196 | AH6: =AG8 -> 383
H7: Issued | I7: 187 | AG7: =I7 -> 187
H8: Grand Total | I8: 383 | AG8: =I8 -> 383
I10: COUNT
H11: C1
H12: AVG | I12: 24 | AF12: =H12 -> AVG | AG12: =I12 -> 24
H13: NEW | I13: 128 | AF13: =H13 -> NEW | AG13: =I13 -> 128
H14: WORN | I14: 107 | AF14: =H14 -> WORN | AG14: =I14 -> 107
H15: Grand Total | I15: 259 | AF15: =H15 -> Grand Total | AG15: =I15 -> 259
I17: COUNT
H18: C1
H19: 3rd | I19: 81 | AF19: =I19 -> 81 | AG19: =I23 -> 0
H20: 2nd | I20: 177 | AF20: =I20 -> 177 | AG20: =I23 -> 0
H21: 1st | I21: 125 | AF21: =I21 -> 125 | AG21: =I23 -> 0
H22: Grand Total | I22: 383 | AF22: =I22 -> 383 | AG22: =I23 -> 0

Sheet OBJ-5
W3: ( Ctrl + p ) Print the Recipt…
D5: BK126
BO7: =D5 -> BK126 | BS7: 1st
BS8: 2nd
N9: HARSH | BS9: 3rd
E10: =BO10 -> NCERT Chemistry | BO10: =IFERROR(VLOOKUP(BO7, DATA_SET!A2:Q7354, 2, FALSE)," ") -> NCERT Chemistry | BS10: 4th
BO11: =IFERROR(VLOOKUP(BO7, DATA_SET!A2:Q7354, 5, FALSE)," ") -> 978-0-352-02233-2
N12: Hno. 88 Mayur Vihar New Delhi 110058 | BO12: =IFERROR(VLOOKUP(BO7, DATA_SET!A2:Q7354,8, FALSE)," ") -> 3rd
E13: =BO11 -> 978-0-352-02233-2 | BO13: =IFERROR(VLOOKUP(BO7, DATA_SET!A2:Q7354, 14, FALSE)," ") -> 835
N15: 9310928752 | BO15: =CHOOSE(C33, "GOOD", "AVERAGE", "WORN") -> GOOD
E16: 4th
N18: tiwariatul1016@gmail.com
E19: =TODAY() -> 45759
E22: NOT MENTION
C27: =BO13 -> 835 | F27: =IFERROR(C27+130," ") -> 965
B31: BOOK CONDITION :
C33: 1
F177: FALSE
F179: TRUE

Sheet DASHBOARD
CL7: Shelf Code | CM7: Availability Status | CN7: Count of Availability Status | CQ7: =VLOOKUP(CP10,CY22:CZ43, 2, FALSE) -> 30 | CS7: Shelf Code | CT7: Availability Status | CU7: Count of Availability Status | DM7: Row Labels | DN7: Sum of Cost
CL8: A1 | CM8: Available | CN8: 13 | CS8: A1 | CT8: Issued | CU8: 16 | CZ8: Row Labels | DA8: Sum of No. Of Rewiew | DM8: Computer Science | DN8: 33845
CM9: Issued | CN9: 16 | CR9: =CQ7 -> 30 | CS9: A1 Total | CU9: 16 | CZ9: AVG | DA9: 812 | DM9: Cambridge | DN9: 11250 | DO9: =DM9 -> Cambridge | DP9: =DN9 -> 11250
CL10: A1 Total | CN10: 29 | CP10: =_xlfn.CONCAT(CP16,CQ16) -> B1 | CQ10: AVL | CR10: =VLOOKUP(CP10,CL7:CN68, 3, FALSE) -> 14 | CS10: A2 | CT10: Issued | CU10: 14 | CZ10: Computer Science | DA10: 812 | DE10: AVG | DF10: NEW | DG10: WORN | DM10: Macmillan | DN10: 4850 | DO10: =DM10 -> Macmillan | DP10: =DN10 -> 4850 | FF10: Count of Book ID | FG10: Column Labels
CL11: A2 | CM11: Available | CN11: 14 | CP11: =CP10 -> B1 | CQ11: ISSUE | CR11: =CQ7 -> 30 | CS11: A2 Total | CU11: 14 | CZ11: NEW | DA11: 782 | DM11: NCERT | DN11: 6040 | DO11: =DM11 -> NCERT | DP11: =DN11 -> 6040 | EK11: 10 | EL11: 100 | FF11: Row Labels | FG11: Cambridge | FH11: Macmillan | FI11: NCERT | FJ11: Oxford | FK11: Pearson | FL11: Scholastic | FM11: Grand Total
BZ12: Row Labels | CA12: Count of Genre | CM12: Issued | CN12: 14 | CR12: =VLOOKUP(CP10,CS7:CU48, 3, FALSE) -> 16 | CS12: A3 | CT12: Issued | CU12: 12 | CZ12: Computer Science | DA12: 782 | DD12: =CZ9 -> AVG | DE12: =DA10 -> 812 | DF12: =DA11 -> 782 | DG12: =DA12 -> 782 | DM12: Oxford | DN12: 5405 | DO12: =DM12 -> Oxford | DP12: =DN12 -> 5405 | EK12: 40 | EL12: 100 | FF12: Computer Science | FG12: 8 | FH12: 4 | FI12: 5 | FJ12: 5 | FK12: 2 | FL12: 2 | FM12: 26
BZ13: Computer Science | CA13: 533 | CB13: PUBLISHER | CC13: TOTAL | CF13: AVG | CL13: A2 Total | CN13: 28 | CS13: A3 Total | CU13: 12 | CZ13: WORN | DA13: 3265 | DM13: Pearson | DN13: 2840 | DO13: =DM13 -> Pearson | DP13: =DN13 -> 2840 | EK13: 50 | EL13: 100 | FF13: Grand Total | FG13: 8 | FH13: 4 | FI13: 5 | FJ13: 5 | FK13: 2 | FL13: 2 | FM13: 26
BZ14: Cambridge | CA14: 80 | CB14: =BZ14 -> Cambridge | CC14: =CA14 -> 80 | CD14: =CA20 -> 533 | CE14: =ROUNDUP(CC14/CD14*100,1) -> 15.1 | CF14: 93 | CL14: A3 | CM14: Available | CN14: 13 | CS14: A4 | CT14: Issued | CU14: 11 | CZ14: Computer Science | DA14: 3265 | DM14: Scholastic | DN14: 3460 | DO14: =DM14 -> Scholastic | DP14: =DN14 -> 3460
BZ15: Macmillan | CA15: 98 | CB15: =BZ15 -> Macmillan | CC15: =CA15 -> 98 | CD15: =CA20 -> 533 | CE15: =ROUNDUP(CC15/CD15*100,1) -> 18.4 | CF15: 93 | CM15: Issued | CN15: 12 | CS15: A4 Total | CU15: 11 | CZ15: Grand Total | DA15: 4859 | DM15: Grand Total | DN15: 33845
BZ16: NCERT | CA16: 102 | CB16: =BZ16 -> NCERT | CC16: =CA16 -> 102 | CD16: =CA20 -> 533 | CE16: =ROUNDUP(CC16/CD16*100,1) -> 19.2 | CF16: 93 | CL16: A3 Total | CN16: 25 | CP16: =BQ26 -> B | CQ16: =BQ25 -> 1 | CS16: B1 | CT16: Issued | CU16: 16
BU17: Row Labels | BV17: Count of Title | BZ17: Oxford | CA17: 96 | CB17: =BZ17 -> Oxford | CC17: =CA17 -> 96 | CD17: =CA20 -> 533 | CE17: =ROUNDUP(CC17/CD17*100,1) -> 18.1 | CF17: 93 | CL17: A4 | CM17: Available | CN17: 12 | CS17: B1 Total | CU17: 16 | EK17: 10 | EL17: 30 | EM17: 60
BU18: Computer Science | BV18: 533 | BZ18: Pearson | CA18: 80 | CB18: =BZ18 -> Pearson | CC18: =CA18 -> 80 | CD18: =CA20 -> 533 | CE18: =ROUNDUP(CC18/CD18*100,1) -> 15.1 | CF18: 93 | CM18: Issued | CN18: 11 | CS18: B2 | CT18: Issued | CU18: 16
BU19: Grand Total | BV19: 533 | BZ19: Scholastic | CA19: 77 | CB19: =BZ19 -> Scholastic | CC19: =CA19 -> 77 | CD19: =CA20 -> 533 | CE19: =ROUNDUP(CC19/CD19*100,1) -> 14.5 | CF19: 93 | CL19: A4 Total | CN19: 23 | CS19: B2 Total | CU19: 16
BZ20: Grand Total | CA20: 533 | CL20: B1 | CM20: Available | CN20: 14 | CS20: B3 | CT20: Issued | CU20: 3 | DE20: Row Labels | DF20: Count of Edition
CM21: Issued | CN21: 16 | CP21: =CP10 -> B1 | CQ21: =CR11 -> 30 | CS21: B3 Total | CU21: 3 | DE21: Computer Science | DF21: 26 | DU21: Row Labels | DV21: Count of Book Condition
BU22: Row Labels | BV22: Count of Availability Status | CL22: B1 Total | CN22: 30 | CP22: =CQ10 -> AVL | CQ22: =CR10 -> 14 | CS22: B4 | CT22: Issued | CU22: 14 | CY22: Shelf Code | CZ22: Count of Availability Status | DE22: 1st | DF22: 9 | DG22: =DF22 -> 9 | DH22: =DF25 -> 26 | DU22: Computer Science | DV22: 23
BU23: Computer Science | BV23: 533 | CL23: B2 | CM23: Available | CN23: 14 | CP23: =CQ11 -> ISSUE | CQ23: =CR12 -> 16 | CS23: B4 Total | CU23: 14 | CY23: A1 | CZ23: 29 | DE23: 2nd | DF23: 12 | DG23: =DF23 -> 12 | DH23: =DF25 -> 26 | DU23: 1st | DV23: 9
BU24: Available | BV24: 270 | CM24: Issued | CN24: 16 | CS24: C1 | CT24: Issued | CU24: 12 | CY24: A2 | CZ24: 28 | DE24: 3rd | DF24: 5 | DG24: =DF24 -> 5 | DH24: =DF25 -> 26 | DU24: WORN | DV24: 7
BO25: 2 | BQ25: 1 | BU25: Issued | BV25: 263 | CL25: B2 Total | CN25: 30 | CS25: C1 Total | CU25: 12 | CY25: A3 | CZ25: 25 | DE25: Grand Total | DF25: 26 | DU25: NEW | DV25: 2 | DZ25: =DV25 -> 2 | EA25: =DV26 -> 9 | EB25: =DV24 -> 7
BQ26: =CHOOSE(BO25, "A", "B", "C", "D", "E") -> B | BU26: Grand Total | BV26: 533 | CL26: B3 | CM26: Available | CN26: 12 | CS26: C2 | CT26: Issued | CU26: 17 | CY26: A4 | CZ26: 23 | DU26: 2nd | DV26: 9 | DZ26: =DV29 -> 5 | EA26: =DV30 -> 5 | EB26: =DV28 -> 1
CA27: Row Labels | CB27: Sum of No. Of Rewiew | CM27: Issued | CN27: 3 | CS27: C2 Total | CU27: 17 | CY27: B1 | CZ27: 30 | DU27: WORN | DV27: 3 | DZ27: =DV33 -> 23 | EA27: =DV34 -> 0 | EB27: =DV32 -> 4
CA28: 2007 | CB28: 7507 | CL28: B3 Total | CN28: 15 | CS28: C3 | CT28: Issued | CU28: 10 | CY28: B2 | CZ28: 30 | DU28: NEW | DV28: 1
BU29: Row Labels | BV29: Sum of No. Of Rewiew | CA29: Cambridge | CB29: 2272 | CC29: =CA29 -> Cambridge | CD29: =CB29 -> 2272 | CE29: =CB35 -> 7507 | CL29: B4 | CM29: Available | CN29: 15 | CS29: C3 Total | CU29: 10 | CY29: B3 | CZ29: 15 | DU29: AVG | DV29: 5
BU30: Computer Science | BV30: 150146 | CA30: Macmillan | CB30: 1396 | CC30: =CA30 -> Macmillan | CD30: =CB30 -> 1396 | CE30: =CB35 -> 7507 | CM30: Issued | CN30: 14 | CS30: C4 | CT30: Issued | CU30: 13 | CY30: B4 | CZ30: 29 | DU30: 3rd | DV30: 5
BU31: 1st | BV31: 51792 | BW31: =BV34 -> 150146 | BX31: =ROUNDUP(BV31/BW31*100,0) -> 35 | BY31: 100 | CA31: NCERT | CB31: 1384 | CC31: =CA31 -> NCERT | CD31: =CB31 -> 1384 | CE31: =CB35 -> 7507 | CL31: B4 Total | CN31: 29 | CS31: C4 Total | CU31: 13 | CY31: C1 | CZ31: 25 | DU31: WORN | DV31: 1
BU32: 2nd | BV32: 64073 | BW32: =BV34 -> 150146 | BX32: =ROUNDUP(BV32/BW32*100,0) -> 43 | BY32: 100 | CA32: Oxford | CB32: 1402 | CC32: =CA32 -> Oxford | CD32: =CB32 -> 1402 | CE32: =CB35 -> 7507 | CL32: C1 | CM32: Available | CN32: 13 | CS32: D1 | CT32: Issued | CU32: 18 | CY32: C2 | CZ32: 33 | DU32: AVG | DV32: 4
BU33: 3rd | BV33: 34281 | BW33: =BV34 -> 150146 | BX33: =ROUNDUP(BV33/BW33*100,0) -> 23 | BY33: 100 | CA33: Pearson | CB33: 617 | CC33: =CA33 -> Pearson | CD33: =CB33 -> 617 | CE33: =CB35 -> 7507 | CM33: Issued | CN33: 12 | CS33: D1 Total | CU33: 18 | CY33: C3 | CZ33: 24 | DU33: Grand Total | DV33: 23
BU34: Grand Total | BV34: 150146 | BW34: =BV35 -> 0 | CA34: Scholastic | CB34: 436 | CC34: =CA34 -> Scholastic | CD34: =CB34 -> 436 | CE34: =CB35 -> 7507 | CL34: C1 Total | CN34: 25 | CS34: D2 | CT34: Issued | CU34: 11 | CY34: C4 | CZ34: 28
CA35: Grand Total | CB35: 7507 | CL35: C2 | CM35: Available | CN35: 16 | CS35: D2 Total | CU35: 11 | CY35: D1 | CZ35: 32
CM36: Issued | CN36: 17 | CS36: D3 | CT36: Issued | CU36: 12 | CY36: D2 | CZ36: 23
CL37: C2 Total | CN37: 33 | CS37: D3 Total | CU37: 12 | CY37: D3 | CZ37: 31
CL38: C3 | CM38: Available | CN38: 14 | CS38: D4 | CT38: Issued | CU38: 13 | CY38: D4 | CZ38: 27
CM39: Issued | CN39: 10 | CS39: D4 Total | CU39: 13 | CY39: E1 | CZ39: 23
AC40: 4 | CL40: C3 Total | CN40: 24 | CS40: E1 | CT40: Issued | CU40: 13 | CY40: E2 | CZ40: 26 | DM40: =CG89/2500*100 -> 29
CL41: C4 | CM41: Available | CN41: 15 | CS41: E1 Total | CU41: 13 | CY41: E3 | CZ41: 27
CM42: Issued | CN42: 13 | CS42: E2 | CT42: Issued | CU42: 17 | CY42: E4 | CZ42: 25 | DM42: =DM40/100 -> 0.29 | DN42: 0.2 | DO42: =DM42-0.025 -> 0.265
CL43: C4 Total | CN43: 28 | CS43: E2 Total | CU43: 17 | CY43: Grand Total | CZ43: 533 | DN43: 0.2 | DO43: 0.08
CL44: D1 | CM44: Available | CN44: 14 | CS44: E3 | CT44: Issued | CU44: 12 | DN44: 0.2
CM45: Issued | CN45: 18 | CS45: E3 Total | CU45: 12 | DN45: 0.2
CL46: D1 Total | CN46: 32 | CS46: E4 | CT46: Issued | CU46: 13 | DN46: 0.2
...

Sheet TABLE
F5: GENRES | O5: PUB.YRS | X5: S.CODE
G6: Cambridge | H6: Macmillan | I6: NCERT | J6: Oxford | K6: Pearson | L6: Scholastic | M6: Grand Total | P6: Cambridge | Q6: Macmillan | R6: NCERT | S6: Oxford | T6: Pearson | U6: Scholastic | V6: Grand Total | Y6: Cambridge | Z6: Macmillan | AA6: NCERT | AB6: Oxford | AC6: Pearson | AD6: Scholastic | AE6: Grand Total
F7: Accountancy | G7: 83 | H7: 100 | I7: 89 | J7: 118 | K7: 104 | L7: 101 | M7: 595 | O7: 2005 | P7: 62 | Q7: 54 | R7: 75 | S7: 67 | T7: 74 | U7: 54 | V7: 386 | X7: A1 | Y7: 59 | Z7: 60 | AA7: 57 | AB7: 58 | AC7: 68 | AD7: 73 | AE7: 375
F8: Biology | G8: 79 | H8: 92 | I8: 119 | J8: 102 | K8: 93 | L8: 91 | M8: 576 | O8: 2006 | P8: 63 | Q8: 54 | R8: 55 | S8: 82 | T8: 52 | U8: 57 | V8: 363 | X8: A2 | Y8: 60 | Z8: 73 | AA8: 55 | AB8: 77 | AC8: 61 | AD8: 63 | AE8: 389
F9: Business Studies | G9: 90 | H9: 94 | I9: 108 | J9: 99 | K9: 89 | L9: 91 | M9: 571 | O9: 2007 | P9: 80 | Q9: 63 | R9: 51 | S9: 58 | T9: 50 | U9: 56 | V9: 358 | X9: A3 | Y9: 47 | Z9: 60 | AA9: 55 | AB9: 60 | AC9: 52 | AD9: 65 | AE9: 339
F10: Chemistry | G10: 106 | H10: 87 | I10: 98 | J10: 94 | K10: 82 | L10: 99 | M10: 566 | O10: 2008 | P10: 62 | Q10: 67 | R10: 58 | S10: 55 | T10: 53 | U10: 51 | V10: 346 | X10: A4 | Y10: 59 | Z10: 69 | AA10: 54 | AB10: 57 | AC10: 51 | AD10: 74 | AE10: 364
F11: Computer Science | G11: 80 | H11: 98 | I11: 102 | J11: 96 | K11: 80 | L11: 77 | M11: 533 | O11: 2009 | P11: 68 | Q11: 62 | R11: 74 | S11: 72 | T11: 50 | U11: 54 | V11: 380 | X11: B1 | Y11: 71 | Z11: 55 | AA11: 67 | AB11: 63 | AC11: 58 | AD11: 66 | AE11: 380
F12: Economics | G12: 86 | H12: 95 | I12: 95 | J12: 88 | K12: 100 | L12: 96 | M12: 560 | O12: 2010 | P12: 62 | Q12: 47 | R12: 65 | S12: 54 | T12: 60 | U12: 69 | V12: 357 | X12: B2 | Y12: 80 | Z12: 65 | AA12: 70 | AB12: 62 | AC12: 75 | AD12: 55 | AE12: 407
F13: English | G13: 84 | H13: 96 | I13: 91 | J13: 86 | K13: 94 | L13: 100 | M13: 551 | O13: 2011 | P13: 59 | Q13: 57 | R13: 69 | S13: 79 | T13: 64 | U13: 70 | V13: 398 | X13: B3 | Y13: 68 | Z13: 48 | AA13: 47 | AB13: 66 | AC13: 68 | AD13: 64 | AE13: 361
F14: EVS | G14: 108 | H14: 100 | I14: 94 | J14: 85 | K14: 98 | L14: 98 | M14: 583 | O14: 2012 | P14: 54 | Q14: 61 | R14: 62 | S14: 72 | T14: 66 | U14: 54 | V14: 369 | X14: B4 | Y14: 62 | Z14: 57 | AA14: 65 | AB14: 63 | AC14: 66 | AD14: 50 | AE14: 363
F15: Hindi | G15: 98 | H15: 86 | I15: 93 | J15: 103 | K15: 90 | L15: 81 | M15: 551 | O15: 2013 | P15: 50 | Q15: 66 | R15: 66 | S15: 74 | T15: 57 | U15: 75 | V15: 388 | X15: C1 | Y15: 64 | Z15: 65 | AA15: 62 | AB15: 67 | AC15: 71 | AD15: 54 | AE15: 383
F16: Maths | G16: 106 | H16: 98 | I16: 84 | J16: 117 | K16: 103 | L16: 110 | M16: 618 | O16: 2014 | P16: 58 | Q16: 60 | R16: 66 | S16: 58 | T16: 64 | U16: 69 | V16: 375 | X16: C2 | Y16: 60 | Z16: 58 | AA16: 63 | AB16: 58 | AC16: 59 | AD16: 59 | AE16: 357
F17: Physics | G17: 104 | H17: 89 | I17: 98 | J17: 99 | K17: 107 | L17: 84 | M17: 581 | O17: 2015 | P17: 52 | Q17: 68 | R17: 60 | S17: 65 | T17: 71 | U17: 71 | V17: 387 | X17: C3 | Y17: 58 | Z17: 64 | AA17: 67 | AB17: 77 | AC17: 63 | AD17: 62 | AE17: 391
F18: Science | G18: 110 | H18: 104 | I18: 84 | J18: 81 | K18: 88 | L18: 95 | M18: 562 | O18: 2016 | P18: 51 | Q18: 76 | R18: 81 | S18: 78 | T18: 64 | U18: 61 | V18: 411 | X18: C4 | Y18: 53 | Z18: 64 | AA18: 66 | AB18: 55 | AC18: 74 | AD18: 75 | AE18: 387
... F20: Grand Total | G20: 1222 | H20: 1248 | I20: 1258 | J20: 1268 | K20: 1229 | L20: 1227 | M20: 7452 | O20: 2018 | P20: 57 | Q20: 63 | R20: 53 | S20: 67 | T20: 62 | U20: 60 | V20: 362 | X20: D2 | Y20: 62 | Z20: 64 | AA20: 48 | AB20: 54 | AC20: 55 | AD20: 55 | AE20: 338
O21: 2019 | P21: 54 | Q21: 69 | R21: 54 | S21: 62 | T21: 50 | U21: 52 | V21: 341 | X21: D3 | Y21: 62 | Z21: 66 | AA21: 74 | AB21: 45 | AC21: 42 | AD21: 60 | AE21: 349
O22: 2020 | P22: 50 | Q22: 70 | R22: 69 | S22: 64 | T22: 69 | U22: 74 | V22: 396 | X22: D4 | Y22: 43 | Z22: 61 | AA22: 65 | AB22: 76 | AC22: 72 | AD22: 56 | AE22: 373
O23: 2021 | P23: 67 | Q23: 62 | R23: 55 | S23: 47 | T23: 61 | U23: 66 | V23: 358 | X23: E1 | Y23: 71 | Z23: 52 | AA23: 53 | AB23: 57 | AC23: 73 | AD23: 58 | AE23: 364
F24: Sum of Cost | O24: 2022 | P24: 72 | Q24: 71 | R24: 58 | S24: 68 | T24: 57 | U24: 59 | V24: 385 | X24: E2 | Y24: 69 | Z24: 66 | AA24: 80 | AB24: 71 | AC24: 63 | AD24: 47 | AE24: 396
G25: Cambridge | H25: Macmillan | I25: NCERT | J25: Oxford | K25: Pearson | L25: Scholastic | M25: Grand Total | O25: 2023 | P25: 59 | Q25: 59 | R25: 57 | S25: 45 | T25: 71 | U25: 62 | V25: 353 | X25: E3 | Y25: 53 | Z25: 57 | AA25: 75 | AB25: 67 | AC25: 50 | AD25: 73 | AE25: 375
F26: Accountancy | G26: 103995 | H26: 137120 | I26: 119440 | J26: 155355 | K26: 152230 | L26: 130155 | M26: 798295 | O26: 2024 | P26: 57 | Q26: 63 | R26: 63 | S26: 58 | T26: 67 | U26: 56 | V26: 364 | X26: E4 | Y26: 63 | Z26: 77 | AA26: 64 | AB26: 69 | AC26: 46 | AD26: 62 | AE26: 381
F27: Biology | G27: 111075 | H27: 111680 | I27: 162855 | J27: 141195 | K27: 118155 | L27: 119045 | M27: 764005 | O27: Grand Total | P27: 1222 | Q27: 1248 | R27: 1258 | S27: 1268 | T27: 1229 | U27: 1227 | V27: 7452 | X27: Grand Total | Y27: 1222 | Z27: 1248 | AA27: 1258 | AB27: 1268 | AC27: 1229 | AD27: 1227 | AE27: 7452
F28: Business Studies | G28: 123395 | H28: 119450 | I28: 136510 | J28: 122380 | K28: 121620 | L28: 117555 | M28: 740910
F29: Chemistry | G29: 141005 | H29: 107945 | I29: 126820 | J29: 121800 | K29: 106945 | L29: 136875 | M29: 741390 | O29: STATUS | X29: EDN
F30: Computer Science | G30: 97900 | H30: 126815 | I30: 131395 | J30: 126410 | K30: 109490 | L30: 111410 | M30: 703420 | P30: Cambridge | Q30: Macmillan | R30: NCERT | S30: Oxford | T30: Pearson | U30: Scholastic | V30: Grand Total | Y30: AVG | Z30: AVG | AA30: NEW | AB30: WORN | AC30: Grand Total
F31: Economics | G31: 110835 | H31: 129025 | I31: 124745 | J31: 117460 | K31: 126830 | L31: 131800 | M31: 740695 | O31: Available | P31: 585 | Q31: 634 | R31: 672 | S31: 642 | T31: 610 | U31: 615 | V31: 3758 | X31: 1st | Y31: 756 | Z31: 216 | AA31: 756 | AB31: 756 | AC31: 2484
F32: English | G32: 115995 | H32: 120945 | I32: 110425 | J32: 109485 | K32: 117800 | L32: 117275 | M32: 691925 | O32: Issued | P32: 637 | Q32: 614 | R32: 586 | S32: 626 | T32: 619 | U32: 612 | V32: 3694 | X32: 2nd | Y32: 1008 | Z32: 288 | AA32: 1008 | AB32: 1008 | AC32: 3312
F33: EVS | G33: 136510 | H33: 129985 | I33: 134755 | J33: 113210 | K33: 126795 | L33: 133555 | M33: 774810 | O33: Grand Total | P33: 1222 | Q33: 1248 | R33: 1258 | S33: 1268 | T33: 1229 | U33: 1227 | V33: 7452 | X33: 3rd | Y33: 504 | Z33: 144 | AA33: 504 | AB33: 504 | AC33: 1656
F34: Hindi | G34: 136985 | H34: 120700 | I34: 130285 | J34: 134170 | K34: 111385 | L34: 104745 | M34: 738270 | X34: Grand Total | Y34: 2268 | Z34: 648 | AA34: 2268 | AB34: 2268 | AC34: 7452
F35: Maths | G35: 139165 | H35: 123745 | I35: 108900 | J35: 148445 | K35: 130680 | L35: 144645 | M35: 795580 | O35: PGS
F36: Physics | G36: 134355 | H36: 109060 | I36: 128600 | J36: 135815 | K36: 142355 | L36: 105780 | M36: 755965 | P36: Cambridge | Q36: Macmillan | R36: NCERT | S36: Oxford | T36: Pearson | U36: Scholastic | V36: Grand Total
F37: Science | G37: 149570 | H37: 140155 | I37: 112015 | J37: 103475 | K37: 114290 | L37: 115655 | M37: 735160 | O37: Available | P37: 170601 | Q37: 176512 | R37: 198197 | S37: 187920 | T37: 176543 | U37: 174966 | V37: 1084739
F38: Social Science | G38: 117970 | H38: 138870 | I38: 142770 | J38: 136645 | K38: 127910 | L38: 138905 | M38: 803070 | O38: Issued | P38: 183122 | Q38: 176749 | R38: 162079 | S38: 177890 | T38: 173989 | U38: 175745 | V38: 1049574
F39: Grand Total | G39: 1618755 | H39: 1615495 | I39: 1669515 | J39: 1665845 | K39: 1606485 | L39: 1607400 | M39: 9783495 | O39: Grand Total | P39: 353723 | Q39: 353261 | R39: 360276 | S39: 365810 | T39: 350532 | U39: 350711 | V39: 2134313
N70: THIS IS R5
